Workbook

Sheet Data
S1: Comentarios
B2: Diario | M2: Semanal
B3: Fechas | C3: Dia | D3: hora | E3: agencia | F3: idioma | G3: Pax | H3: Utilidad | I3: Costo | J3: Ingreso | K3: Bookings | L3: X Tip PAX | M3: Bookings | N3: Asistencia | O3: Nro tours | P3: Pax | Q3: Tipo tour | R3: Enero
A4: Semana 1 | B4: 2 enero | C4: lunes | M4: =SUM(K4:K10) -> 138 | N4: =P4/M4 -> 0.71014493 | O4: =4 -> 4 | P4: =SUM(G4:G10) -> 98
B5: 3 enero | C5: martes | D5: 11AM | E5: SDM | F5: Español | G5: 36 | H5: =J5-(2.5*G5) -> 260 | I5: 90 | J5: =350 -> 350 | K5: =40 -> 40 | L5: =J5/G5 -> 9.7222222 | Q5: city corto
B6: 4 enero | C6: miercoles
B7: 5 enero | C7: jueves | D7: 11AM | E7: CYT | F7: Ingles | G7: 15 | H7: =160 -> 160 | I7: =0 -> 0 | J7: =160 -> 160 | K7: =23 -> 23 | L7: =J7/G7 -> 10.666667 | Q7: city largo
B8: 6 enero | C8: viernes
B9: 7 enero | C9: sabado | D9: 11AM | E9: SDM | F9: Español | G9: 26 | H9: 190 | I9: 65 | J9: =255 -> 255 | K9: =50 -> 50 | L9: =J9/G9 -> 9.8076923 | Q9: city corto
B10: 8 enero | C10: domingo | D10: 11AM | E10: SDM | F10: Español | G10: 21 | H10: 195.5 | I10: 52.5 | J10: =248 -> 248 | K10: =25 -> 25 | L10: =J10/G10 -> 11.809524 | Q10: city corto
A11: Semana 2 | B11: 9 enero | C11: Lunes | M11: =SUM(K11:K17) -> 68 | N11: =P11/M11 -> 0.66176471 | O11: =2 -> 2 | P11: =G16+G17 -> 45
B12: 10 enero | C12: martes
B13: 11 Enero | C13: miercoles | D13: Cancelado | E13: CYT n
B14: 12 enero | C14: Jueves
B15: 13 Enero | C15: viernes | D15: Cancelado | E15: CYT n
B16: 14 enero | C16: sabado | D16: 11AM | E16: SDM | F16: Español | G16: 28 | H16: =J16-(2.5*G16) -> 225 | I16: =70 -> 70 | J16: =295 -> 295 | K16: =38 -> 38 | L16: =J16/G16 -> 10.535714 | Q16: city corto
B17: 15 enero | C17: domingo | D17: 11AM | E17: SDM | F17: Español | G17: 17 | H17: =92.5 -> 92.5 | I17: 42.5 | J17: =135 -> 135 | K17: =30 -> 30 | L17: =J17/G17 -> 7.9411765 | Q17: city corto
A18: Semana 3 | B18: 16 enero | C18: Lunes | K18: =0 -> 0 | M18: =SUM(K18:K25) -> 121 | N18: =P18/M18 -> 0.84297521 | O18: =4 -> 4 | P18: =SUM(G18:G25) -> 102
B19: 17 enero | C19: martes | D19: 11AM | E19: SDM | F19: Español | G19: =8 -> 8 | H19: =70 -> 70 | I19: =20 -> 20 | J19: =90 -> 90 | K19: =15 -> 15 | L19: =J19/G19 -> 11.25 | Q19: city corto
B20: 18 enero | C20: miercoles | D20: Cancelado | E20: CYT n
B21: 19 enero | C21: Jueves | D21: 11AM | E21: SDM | F21: Español | G21: =16 -> 16 | H21: =120 -> 120 | I21: =40 -> 40 | J21: =160 -> 160 | K21: =18 -> 18 | L21: =J21/G21 -> 10 | Q21: city corto
B22: 20 enero | C22: viernes
B23: 21 enero | C23: sabado | D23: 11AM | E23: SDM | F23: Español | G23: =49 -> 49 | H23: =285 -> 285 | I23: =107.5 -> 107.5 | J23: =392.5 -> 392.5 | K23: =50 -> 50 | L23: =J23/G23 -> 8.0102041 | Q23: city corto
B24: 22 enero | C24: domingo | D24: 11am | E24: SDM | F24: Ingles | G24: =29 -> 29 | H24: =142 -> 142 | I24: =65 -> 65 | J24: =207.5 -> 207.5 | K24: =38 -> 38 | L24: =J24/G24 -> 7.1551724 | Q24: city corto
B25: 22 enero | C25: domingo | D25: Cancelado | E25: SDM
A26: Semana 4 | B26: 23 enero | C26: Lunes | M26: =SUM(K26:K32) -> 98 | N26: =P26/M26 -> 0.85714286 | O26: =3 -> 3 | P26: =SUM(G26:G31) -> 84
B27: 24 enero | C27: martes | D27: 11AM | E27: SDM | F27: Ingles | G27: =29 -> 29 | H27: =180 -> 180 | I27: =65 -> 65 | J27: =245 -> 245 | K27: =34 -> 34 | L27: =J27/G27 -> 8.4482759 | Q27: city corto
B28: 25 enero | C28: miercoles | D28: Cancelado | E28: CYT n
B29: 26 enero | C29: Jueves | D29: 11AM | E29: SDM | F29: Ingles | G29: =19 -> 19 | H29: =108 -> 108 | I29: =47.5 -> 47.5 | J29: 155.5 | K29: =24 -> 24 | L29: =J29/G29 -> 8.1842105 | Q29: city corto
B30: 27 enero | C30: viernes
B31: 28 enero | C31: sabado | D31: 11AM | E31: SDM | F31: Español | G31: =36 -> 36 | H31: =270 -> 270 | I31: =90 -> 90 | J31: =360 -> 360 | K31: =40 -> 40 | L31: =J31/G31 -> 10 | Q31: city corto
B32: 29 enero | C32: domingo
A33: 1era semana | B33: 30 enero | C33: Lunes | M33: =SUM(K35:K40)+K34 -> 80 | N33: =P33/M33 -> 0.95 | O33: =4 -> 4 | P33: =SUM(G35:G39)+G34 -> 76
B34: 31 enero | C34: martes | D34: 11AM | E34: SDM | F34: Español | G34: =10 -> 10 | H34: 57.5 | I34: 17.5 | J34: =75 -> 75 | K34: =12 -> 12 | L34: =J34/G34 -> 7.5 | Q34: city corto
B35: 1 febrero | C35: miercoles | D35: 11AM | E35: SDM | F35: Español | G35: =21 -> 21 | H35: =137.5 -> 137.5 | I35: =47.5 -> 47.5 | J35: =185 -> 185 | K35: =14 -> 14 | L35: =J35/G35 -> 8.8095238 | Q35: city corto | R35: Febrero
B36: 2 febrero | C36: Jueves | D36: 11AM | E36: SDM | F36: Ingles | G36: =14 -> 14 | H36: =115 -> 115 | I36: =35 -> 35 | J36: =150 -> 150 | K36: =19 -> 19 | L36: =J36/G36 -> 10.714286 | Q36: city corto
B37: 3 febrero | C37: viernes
B38: 4 febrero | C38: sabado | D38: 11AM | E38: SDM | F38: Español | G38: =31 -> 31 | H38: =205 -> 205 | I38: =70 -> 70 | J38: =275 -> 275 | K38: =35 -> 35 | L38: =J38/G38 -> 8.8709677 | Q38: city corto
B39: 5 febrero | C39: domingo
A40: 2da semana | B40: 6 febrero | C40: Lunes | M40: =SUM(G40:G48) -> 125 | N40: =M40/P40 -> 0.75301205 | O40: =5 -> 5 | P40: =SUM(K40:K48) -> 166
...

Sheet Analisis semanal
A3: Dia | B3: Ratio T/P | C3: Tipo tour | D3: % asistencia | E3: total semana | F3: Tip semana | G3: pago semana | H3: % Propina/total | I3: X TIp por Per | J3: X Pax tour | K3: X $ tour | L3: X $ tour in
A4: martes | B4: =Data!J5/Data!G5 -> 9.7222222 | C4: city corto | D4: =Data!G5/Data!K5 -> 0.9 | E4: =SUM(Data!J5:J10) -> 1013 | F4: =SUM(Data!H5:H10) -> 805.5 | G4: =SUM(Data!I5:I10) -> 207.5 | H4: =SUM(F4/E4) -> 0.79516288 | I4: =AVERAGE(B4:B7) -> 10.501526 | J4: =Data!P4/Data!O4 -> 24.5 | K4: =E4/Data!O4 -> 253.25 | L4: =F4/Data!O4 -> 201.375 | M4: Enero
A5: jueves | B5: =Data!J7/Data!G7 -> 10.666667 | C5: city largo | D5: =Data!G7/Data!K7 -> 0.65217391
A6: sabado | B6: =Data!J9/Data!G9 -> 9.8076923 | C6: city corto | D6: =Data!G9/Data!K9 -> 0.52
A7: domingo | B7: =Data!J10/Data!G10 -> 11.809524 | C7: city corto | D7: =Data!G10/Data!K10 -> 0.84
A8: sabado | B8: =Data!J16/Data!G16 -> 10.535714 | C8: city corto | D8: =Data!G16/Data!K16 -> 0.73684211 | E8: =Data!J16+Data!J17 -> 430 | F8: =Data!H16+Data!H17 -> 317.5 | G8: =Data!I16+Data!I17 -> 112.5 | H8: =F8/E8 -> 0.73837209 | I8: =AVERAGE(B8:B9) -> 9.2384454 | J8: =Data!P11/Data!O11 -> 22.5 | K8: =E8/Data!O11 -> 215 | L8: =F8/Data!O11 -> 158.75
A9: domingo | B9: =Data!J17/Data!G17 -> 7.9411765 | C9: city corto | D9: =Data!G17/Data!K17 -> 0.56666667
A10: martes | B10: =Data!J19/Data!G19 -> 11.25 | C10: city corto | D10: =Data!G19/Data!K19 -> 0.53333333 | E10: =SUM(Data!J19:J25) -> 850 | F10: =SUM(Data!H19:H25) -> 617 | G10: =SUM(Data!I18:I25) -> 232.5 | H10: =F10/E10 -> 0.72588235 | I10: =AVERAGE(B10:B14) -> 8.9727305 | J10: =Data!P18/Data!O18 -> 25.5 | K10: =E10/Data!O18 -> 212.5 | L10: =F10/Data!O18 -> 154.25
A11: jueves | B11: =Data!J21/Data!G21 -> 10 | C11: city corto | D11: =Data!G21/Data!K21 -> 0.88888889
A12: sabado | B12: =Data!J23/Data!G23 -> 8.0102041 | C12: city corto | D12: =Data!G23/Data!K23 -> 0.98
A13: domingo | B13: =Data!J24/Data!G24 -> 7.1551724 | C13: city corto | D13: =Data!G24/Data!K24 -> 0.76315789
A14: martes | B14: =Data!J27/Data!G27 -> 8.4482759 | C14: city corto | D14: =Data!G27/Data!K27 -> 0.85294118 | E14: =SUM(Data!J26:J32) -> 760.5 | F14: =SUM(Data!H26:H32) -> 558 | G14: =SUM(Data!I26:I32) -> 202.5 | H14: =F14/E14 -> 0.73372781 | I14: =AVERAGE(B14:B16) -> 8.0441621 | J14: =Data!P26/Data!O26 -> 28 | K14: =E14/Data!O26 -> 253.5 | L14: =F14/Data!O26 -> 186
A15: jueves | B15: =Data!J29/Data!G29 -> 8.1842105 | C15: city corto | D15: =Data!G29/Data!K29 -> 0.79166667
A16: sabado | B16: =Data!J34/Data!G34 -> 7.5 | C16: city corto | D16: =Data!G31/Data!K31 -> 0.9
A17: martes | B17: =Data!J34/Data!G34 -> 7.5 | C17: city corto | D17: =Data!G34/Data!K34 -> 0.83333333 | E17: =SUM(Data!J35:J39)+85 -> 695 | F17: =Data!H34+SUM(Data!H35:H39) -> 515 | G17: =Data!I34+SUM(Data!I35:I39) -> 170 | H17: =F17/E17 -> 0.74100719 | I17: =AVERAGE(B17:B20) -> 8.9736943 | J17: =Data!P33/Data!O33 -> 19 | K17: =E17/Data!O33 -> 173.75 | L17: =F17/Data!O33 -> 128.75 | M17: Febrero
A18: miercoles | B18: =Data!J35/Data!G35 -> 8.8095238 | C18: city corto | D18: =Data!G35/Data!K35 -> 1.5
A19: jueves | B19: =Data!J36/Data!G36 -> 10.714286 | C19: city corto | D19: =Data!G36/Data!K36 -> 0.73684211
A20: Sabado | B20: =Data!J38/Data!G38 -> 8.8709677 | C20: city corto | D20: =Data!G38/Data!K38 -> 0.88571429
A21: martes | B21: =Data!J41/Data!G41 -> 8.4615385 | C21: city corto | D21: =Data!G41/Data!K41 -> 0.37142857 | E21: =SUM(Data!J40:J48) -> 1236 | F21: =SUM(Data!H40:H48) -> 913.2 | G21: =SUM(Data!I40:I48) -> 322.8 | H21: =F21/E21 -> 0.73883495 | I21: =AVERAGE(B21:B24) -> 9.9062937 | J21: =Data!P40/Data!O40 -> 33.2 | K21: =E21/Data!O40 -> 247.2 | L21: =F21/5 -> 182.64
A22: miercoles | B22: =Data!J42/Data!G42 -> 11.5 | C22: city largo | D22: =Data!G42/Data!K42 -> 0.9
A23: viernes | B23: =Data!J45/Data!G45 -> 8.8636364 | C23: city corto | D23: =Data!G45/Data!K45 -> 0.97777778
A24: sabado | B24: =Data!J46/Data!G46 -> 10.8 | C24: city corto | D24: =Data!G46/Data!K46 -> 0.85714286
A25: domingo | B25: =Data!J48/Data!G48 -> 10.25 | C25: city corto | D25: =Data!G48/Data!K48 -> 0.64516129
A26: lunes | B26: =Data!J49/Data!G49 -> 8.3139535 | C26: city corto | D26: =Data!G49/Data!K49 -> 0.95555556 | E26: =SUM(Data!J49:J57) -> 2038 | F26: =SUM(Data!H49:H57) -> 1384 | G26: =SUM(Data!I49:I57) -> 651 | H26: =F26/E26 -> 0.67909715 | I26: =AVERAGE(B26:B34) -> 9.6463885 | J26: =Data!P49/Data!O49 -> 32.571429 | K26: =E26/Data!O49 -> 291.14286 | L26: =F26/Data!O49 -> 197.71429
A27: lunes | B27: =Data!J50/Data!G50 -> 8.2258065 | C27: city largo | D27: =Data!G50/Data!K50 -> 0.86111111
A28: martes | B28: =Data!J51/Data!G51 -> 9.0444444 | C28: city corto | D28: =Data!G51/Data!K51 -> 0.88235294
A29: viernes | B29: =Data!L54 -> 8.45 | C29: city corto | D29: =Data!G54/Data!K54 -> 0.66666667
A30: viernes | B30: =Data!L55 -> 9.7916667 | C30: city largo | D30: =Data!G55/Data!K55 -> 0.6
A31: sabado | B31: =Data!L56 -> 10.208333 | C31: city largo | D31: =Data!G56/Data!K56 -> 0.75
A32: domingo | B32: =Data!L57 -> 9.1935484 | C32: city corto | D32: =Data!G57/Data!K57 -> 0.81578947
A33: martes | B33: =Data!L59 -> 11.923077 | C33: city corto | D33: =Data!G59/Data!K59 -> 0.68421053 | E33: =SUM(Data!J58:J66) -> 1500 | F33: =SUM(Data!H58:H66) -> 1180 | G33: =SUM(Data!I58:I66) -> 349 | H33: =F33/E33 -> 0.78666667 | I33: =AVERAGE(B33:B39) -> 11.276649 | J33: =Data!P58/Data!O58 -> 19.285714 | K33: =E33/Data!O58 -> 214.28571 | L33: =F33/Data!O58 -> 168.57143
A34: miercoles | B34: =Data!L60 -> 11.666667 | C34: city largo | D34: =Data!G60/Data!K60 -> 0.57692308
A35: jueves | B35: =Data!L61 -> 7.4074074 | C35: city corto | D35: =Data!G61/Data!K61 -> 0.81818182
A36: viernes | B36: =Data!L62 -> 16.136364 | C36: city corto | D36: =Data!G62/Data!K62 -> 0.52380952
A37: sabado | B37: =Data!L63 -> 10 | C37: city corto | D37: =Data!G63/Data!K63 -> 0.6
A38: domingo | B38: =Data!L65 -> 11.136364 | C38: city corto | D38: =Data!G65/Data!K65 -> 0.62857143
A39: domingo | B39: =Data!L66 -> 10.666667 | C39: city corto | D39: =Data!G66/Data!K66 -> 0.6
A40: lunes | B40: =Data!L67 -> 10.322581 | C40: city corto | D40: =Data!G67/Data!K67 -> 0.68888889 | E40: =SUM(Data!J67:J76) -> 1874.5 | F40: =SUM(Data!H67:H75) -> 1419.5 | G40: =SUM(Data!I67:I75) -> 454 | H40: =F40/E40 -> 0.7572686 | I40: =AVERAGE(B40:B46) -> 10.034657 | J40: =Data!P67/Data!O67 -> 29.833333 | K40: =E40/Data!O67 -> 312.41667 | L40: =F40/Data!O67 -> 236.58333
A41: jueves | B41: =Data!L71 -> 9.7142857 | C41: city corto | D41: =Data!G71/Data!K71 -> 0.7 | M41: Marzo
A42: viernes | B42: =Data!L72 -> 8.2692308 | C42: citi largo | D42: =Data!G72/Data!K72 -> 0.8125
...

Sheet Resumen meses
C2: Agencias | D2: Idiomas | E2: Personas | F2: Ingreso total | G2: Pago | H2: Total | I2: % utilidad | J2: Bookings | K2: Asistencia | L2: Nro Tours | M2: X tours week | N2: Ingreso X | O2: Pax X | P2: Tip X | Q2: X diario | R2: Reviews | S2: Tasa reviews | T2: X semanal | U2: Reportados | V2: Recorte | W2: Reviews Totales
B3: Resumen Enero | C3: 1C 13S | D3: 6I 14E | E3: 339 | F3: 2355.5 | G3: 772.5 | H3: 3128.5 | I3: =F3/H3 -> 0.75291673 | J3: 437 | K3: 0.78107221 | L3: 14 | M3: =AVERAGE(Data!O4:O25,4) -> 3.5 | N3: =AVERAGE(Data!H4:H34) -> 168.25 | O3: =AVERAGE(Data!G5:G34) -> 24.214286 | P3: =AVERAGE('Analisis semanal'!B4:B17) -> 9.1807756 | Q3: =F3/31 -> 75.983871 | U3: =G3/2.5 -> 309 | V3: =(E3/U3)-1 -> 0.097087379 | W3: =SUM(R6:R1048576) -> 822
B4: Resumen Febrero | C4: 1D 5C 17S | D4: 13I 10E | E4: =SUM(Data!G35:G68) -> 585 | F4: =SUM(Data!H35:H68) -> 4189.7 | G4: =SUM(Data!I35:I68) -> 1540.3 | H4: =SUM(Data!J35:J68) -> 5704 | I4: =F4/H4 -> 0.73451964 | J4: =SUM(Data!K35:K68) -> 781 | K4: =E4/J4 -> 0.74903969 | L4: =SUM(Data!O40:O66)+3+1 -> 23 | M4: =AVERAGE(Data!O40:O65,3) -> 5.5 | N4: =AVERAGE(Data!H35:H68) -> 182.16087 | O4: =AVERAGE(Data!G35:G68) -> 25.434783 | P4: =AVERAGE('Analisis semanal'!B18:B37) -> 9.931561 | Q4: =F4/28 -> 149.63214 | U4: =G4/2.5 -> 616.12 | V4: =(E4/U4)-1 -> -0.050509641
B5: Resumen Marzo | C5: 4c 17s | D5: 15I 6e | E5: =SUM(Data!G71:G107) -> 469 | F5: =SUM(Data!H71:H107) -> 3620.5 | G5: =SUM(Data!I71:I107) -> 1262 | H5: =SUM(Data!J71:J107) -> 4881 | I5: =F5/H5 -> 0.74175374 | J5: =SUM(Data!K71:K107) -> 646 | K5: =E5/J5 -> 0.72600619 | L5: =21 -> 21 | M5: =AVERAGE(Data!O77:O102,4,2) -> 4 | N5: =AVERAGE(Data!H71:H107) -> 190.55263 | O5: =AVERAGE(Data!G71:G102) -> 24.684211 | P5: =AVERAGE('Analisis semanal'!B42:B59) -> 10.519771 | Q5: =F5/31 -> 116.79032 | U5: =G5/2.5 -> 504.8 | V5: =(E5/U5)-1 -> -0.070919176
B6: Resumen Abril | C6: 24 s C2 | D6: 14I 12 E | E6: =SUM(Data!G109:G144) -> 602 | F6: =SUM(Data!H109:H145)+64 -> 5005.7 | G6: =SUM(Data!I109:I145) -> 1377.5 | H6: =SUM(Data!J109:J145) -> 6316.5 | I6: =F6/H6 -> 0.79248001 | J6: =SUM(Data!K109:K144) -> 768 | K6: =E6/J6 -> 0.78385417 | L6: =SUM(Data!O103:O140) -> 26 | M6: =AVERAGE(Data!O111:O143) -> 6 | N6: =AVERAGE(Data!H109:H144) -> 191.768 | O6: =AVERAGE(Data!G109:G144) -> 24.08 | P6: =AVERAGE('Analisis semanal'!B60:B85) -> 10.271451 | Q6: =F6/30 -> 166.85667 | R6: =64 -> 64 | S6: =R6/U6 -> 0.11615245 | T6: =AVERAGE('Analisis semanal'!F62,'Analisis semanal'!F79) -> 1507.25 | U6: =G6/2.5 -> 551 | V6: =(E6/U6)-1 -> 0.092558984
B7: Resumen Mayo | C7: 23 S 1C | D7: 10I 18E | E7: =SUM(Data!G146:G178) -> 668 | F7: =SUM(Data!H146:H178)+92+33.5 -> 5017.5 | G7: =SUM(Data!I146:I178) -> 1522.9 | H7: =SUM(Data!J146:J178) -> 6321.8 | I7: =F7/H7 -> 0.79368218 | J7: =SUM(Data!K146:K178) -> 850 | K7: =E7/J7 -> 0.78588235 | L7: =23 -> 23 | M7: =AVERAGE(Data!O146:O175) -> 6 | N7: =AVERAGE(Data!H146:H178) -> 203.83333 | O7: =AVERAGE(Data!G146:G178) -> 27.833333 | P7: =AVERAGE('Analisis semanal'!B86:B111) -> 9.6980361 | Q7: =F7/31 -> 161.85484 | R7: =92 -> 92 | S7: =R7/U7 -> 0.15102764 | T7: =AVERAGE('Analisis semanal'!F86:F111) -> 1223 | U7: =G7/2.5 -> 609.16 | V7: =(E7/U7)-1 -> 0.096592028
B8: Resumen Junio | C8: 26 sdm | D8: 16 I 9E | E8: =SUM(Data!G182:G216) -> 755 | F8: =SUM(Data!H182:H216)+63+23+37+24 -> 5858.5 | G8: =SUM(Data!I182:I216) -> 1750 | H8: =SUM(Data!J182:J216) -> 7446.5 | I8: =F8/H8 -> 0.78674545 | J8: =SUM(Data!K182:K216) -> 1124 | K8: =E8/J8 -> 0.67170819 | L8: =26 -> 26 | M8: =AVERAGE(5,5,8,5,8) -> 6.2 | N8: =AVERAGE(Data!H179:H216) -> 228.46 | O8: =AVERAGE(Data!G179:G216) -> 30.2 | P8: =AVERAGE('Analisis semanal'!B112:B138) -> 10.033141 | Q8: =F8/31 -> 188.98387 | R8: =147 -> 147 | S8: =R8/U8 -> 0.21 | T8: =AVERAGE('Analisis semanal'!F112:F135) -> 1328.625 | U8: =G8/2.5 -> 700 | V8: =(E8/U8)-1 -> 0.078571429
B9: Resumen Julio | C9: sdm | D9: 11 E 16I | E9: =SUM(Data!G217:G253) -> 637 | F9: =SUM(Data!H217:H253)+R9 -> 5626 | G9: =SUM(Data!I217:I253) -> 1360 | H9: =SUM(Data!J217:J253) -> 6783.5 | I9: =F9/H9 -> 0.82936537 | J9: =SUM(Data!K217:K253) -> 990 | K9: =E9/J9 -> 0.64343434 | L9: =27 -> 27 | M9: =AVERAGE(Data!O212:O252) -> 5.8 | N9: =AVERAGE(Data!H217:H253) -> 199.37037 | O9: =AVERAGE(Data!G217:G253) -> 23.592593 | P9: =AVERAGE('Analisis semanal'!B139:B170) -> 10.56934 | Q9: =F9/31 -> 181.48387 | R9: =47+24+59+53+43+17 -> 243 | S9: =R9/U9 -> 0.44669118 | T9: =AVERAGE('Analisis semanal'!F142:F163) -> 1304.5 | U9: =G9/2.5 -> 544 | V9: =(E9/U9)-1 -> 0.17095588
B10: Resumen Agosto | C10: 26 | E10: =SUM(Data!G255:G284) -> 634 | F10: =SUM(Data!H255:H288)+R10 -> 5541 | G10: =SUM(Data!I255:I288) -> 1523.5 | H10: =SUM(Data!J255:J288) -> 6817.5 | I10: =F10/H10 -> 0.81276128 | J10: =SUM(Data!K255:K283) -> 948 | K10: =E10/J10 -> 0.66877637 | L10: =26 -> 26 | M10: =AVERAGE(Data!O253:O284) -> 6.6 | N10: =AVERAGE(Data!H254:H284) -> 211.30435 | O10: =AVERAGE(Data!G254:G284) -> 27.565217 | P10: =AVERAGE('Analisis semanal'!B169:B199) -> 10.140573 | Q10: =F10/31 -> 178.74194 | R10: =25+3+8+13+16+2+14+6+14+10+6+16+9+17+7+8+4+15+11+3+12+4+10+14 -> 247 | S10: =R10/U10 -> 0.4053167 | T10: =AVERAGE('Analisis semanal'!F168:F197) -> 1310.8 | U10: =G10/2.5 -> 609.4 | V10: =(E10/U10)-1 -> 0.040367575
B11: Resumen septiembre | E11: =SUM(Data!G289:G318) -> 120 | F11: =SUM(Data!H289:H318) -> 896.5 | G11: =SUM(Data!I289:I318) -> 272.5 | H11: =SUM(Data!J289:J318) -> 1169 | I11: =F11/H11 -> 0.76689478 | J11: =SUM(Data!K289:K318) -> 160 | K11: =E11/J11 -> 0.75 | N11: =AVERAGE(Data!H289:H318) -> 224.125 | O11: =AVERAGE(Data!G289:G318) -> 30 | P11: =AVERAGE('Analisis semanal'!B200:B230) -> 9.6124792 | Q11: =F117/30 -> 0 | R11: =4+4+10+11 -> 29 | S11: =R11/U11 -> 0.26605505 | U11: =G11/2.5 -> 109 | V11: =(E11/U11)-1 -> 0.10091743

Sheet Ahorro
A1: Usuario cyt | B1: practicante1@culturetouringberlin.com
B2: practicante2@culturetouringberlin.com | G2: en box | H2: Lavado | I2: total
F3: 1 marzo | G3: 6200$ | H3: 6440
A4: Pass | B4: Berlin-2022 | F4: 1 Abril | G4: 1900 | H4: 100 | J4: gasto
B5: Donicus | F5: 15 Abril | H5: 100
F6: abril 21 | H6: =100 -> 100
A7: Sum up | B7: controlberlin@gmail.com | F7: 30 abril | G7: 5000 | H7: 300 | I7: =G7+H7 -> 5300 | K7: =SUM(J12:J14)+167 -> 167
B8: Berlin2022 | G8: 8600 | H8: 600
C9: Ahorro mes
A10: Ahorro | B10: Enero | C10: 1100 | D10: Total ahorrado | E10: Meta | F10: promedio para meta
B11: Febrero | C11: 3200 | D11: =SUM(C10:C26)+600-1000 -> 20700 | E11: =22200 -> 22200 | F11: =E11/9 -> 2466.6667
B12: Marzo | C12: 1900 | D12: Promedio actual | E12: Faltan | F12: Ahorros totales
B13: Abril | C13: 3400 | D13: =AVERAGE(C11:C31) -> 2500 | E13: =E11-D11 -> 1500 | F13: =26400+D11 -> 47100
B14: mayo | C14: =3600 -> 3600
B15: Junio | C15: =1900 -> 1900
A16: *9900 cash 3 Julio | B16: Julio | C16: =2100 -> 2100 | E16: monto | F16: fecha | H16: =AVERAGE(I17:I24) -> 0.55342113 | I16: % ahorro | L16: Divisas
A17: debo 84 23/7 | B17: Agosto | C17: =3200 -> 3200 | E17: =356 -> 356 | F17: 2 al 8 julio | H17: enero | I17: =C10/'Resumen meses'!F3 -> 0.46699215 | K17: Dolares | L17: 180
B18: Septiembre | C18: =700 -> 700 | E18: =163 -> 163 | F18: 9 al 15 julio | H18: febrero | I18: =C11/'Resumen meses'!F4 -> 0.76377784 | K18: Libras | L18: 45
D19: Total | E19: =343 -> 343 | F19: 16 al 22 julio | H19: marzo | I19: =C12/'Resumen meses'!F5 -> 0.52478939 | K19: francos | L19: 10
D20: =SUM(E17:E30) -> 2640.5 | E20: =243.5 -> 243.5 | F20: 23 al 29 julio | H20: abril | I20: =C13/'Resumen meses'!F6 -> 0.67922568
D21: Debo 52 | E21: =143.5 -> 143.5 | F21: 30 al 5 agosto | H21: mayo | I21: =C14/'Resumen meses'!F7 -> 0.71748879
E22: =359 -> 359 | F22: 5 al 13 agosto | H22: junio | I22: =C15/'Resumen meses'!F8 -> 0.3243151
E23: =389.5 -> 389.5 | F23: 13 al 19 | H23: julio | I23: =C16/'Resumen meses'!F9 -> 0.37326697
E24: =307 -> 307 | F24: 20 al 26 | H24: Agosto | I24: =C17/'Resumen meses'!F10 -> 0.57751308
E25: =174 -> 174 | F25: 27 al 2 | H25: Septiembre | I25: =C18/'Resumen meses'!F11 -> 0.78081428
E26: =162 -> 162 | F26: 2 al 11

Sheet Promedios siempre
C3: X Tips x per | D3: X Semanal | E3: X tour utilidad | F3: X asistencia | G3: X pax per tour | H3: X dias trabajados por semana | I3: Total tours | J3: Total Pax | K3: X pax semanal
C4: =AVERAGE('Analisis semanal'!B17:B999996) -> 10.143791 | D4: =AVERAGE('Analisis semanal'!F21,'Analisis semanal'!F26,'Analisis semanal'!F46,'Analisis semanal'!F40,'Analisis semanal'!F51,'Analisis semanal'!F62,'Analisis semanal'!F71,'Analisis semanal'!F79,'Analisis semanal'!F86,'Analisis semanal'!F92,'Analisis semanal'!F100,'Analisis semanal'!F108,'Analisis semanal'!F112,'Analisis semanal'!F122,'Analisis semanal'!F126,'Analisis semanal'!F131,'Analisis semanal'!F136) -> 1212.0125 | E4: =AVERAGE('Analisis semanal'!L4:L25000) -> 187.59585 | F4: =AVERAGE('Analisis semanal'!H4:H2600) -> 0.7647778 | G4: =AVERAGE(Data!G5:G1048576) -> 26.144385 | H4: =AVERAGE(Data!O34:O6504) -> 5.75 | I4: =SUM(Data!O4:O1048576) -> 201 | J4: =SUM(Data!P4:P81000) -> 5106 | K4: =AVERAGE(Data!P40:P1048576) -> 146.90625
D8: Ingreso | E8: Costo | F8: Utilidad | G8: Ahorro | H8: Amparo | I8: Ahorro
D9: =SUM('Resumen meses'!H3:H10) -> 47399.3 | E9: =SUM('Resumen meses'!G3:G10) -> 11108.7 | F9: =SUM('Resumen meses'!F3:F10) -> 37214.4 | G9: =Ahorro!D11+700 -> 21400 | H9: =F9*0.01 -> 372.144 | I9: =G9/F9 -> 0.57504622
A13: Evaluacion | B13: Criterio
A14: Malo | B14: 7-7.9
A15: Regular | B15: 8-8.9
A16: Bueno | B16: 9-9.9
A17: Muy Bueno | B17: 10<

Sheet Tipo tours
B2: City Corto | H2: City Largo | N2: Reich | T2: Rojo
B3: Qt tours | C3: QT pax | D3: Asistencia | E3: Total $ | F3: X Pax | G3: Tip x pax | H3: Qt tours | I3: QT pax | J3: Asistencia | K3: Total $ | L3: X Pax | M3: Tip x pax | N3: Qt tours | O3: QT pax | P3: Asistencia | Q3: Total $ | R3: X Pax | T3: Qt tours | U3: QT pax | V3: Asistencia | W3: Total $ | X3: X Pax
B4: =COUNTIF(Data!Q5:Q1048576,"city corto") -> 151 | C4: =SUMIFS(Data!G4:G1048576,Data!Q4:Q1048576,"city corto") -> 3783 | D4: =AVERAGEIFS('Analisis semanal'!D4:D1048576,'Analisis semanal'!C4:C1048576,"city corto") -> 0.74807938 | E4: =SUMIFS(Data!J4:J1048576,Data!Q4:Q1048576,"city corto") -> 37457.8 | F4: =C4/B4 -> 25.05298 | G4: =E4/C4 -> 9.9016125 | H4: =COUNTIF(Data!Q5:Q1048576,"city largo") -> 12 | I4: =SUMIFS(Data!G4:G1048576,Data!Q4:Q1048576,"city largo") -> 294 | J4: =AVERAGEIFS('Analisis semanal'!D4:D1048576,'Analisis semanal'!C4:C1048576,"city largo") -> 0.79462109 | K4: =SUMIFS(Data!J4:J1048576,Data!Q4:Q1048576,"city largo") -> 2922 | L4: =I4/H4 -> 24.5 | M4: =K4/I4 -> 9.9387755 | N4: =COUNTIF(Data!Q5:Q1048576,"reich") -> 12 | O4: =SUMIFS(Data!G4:G1048576,Data!Q4:Q1048576,"reich") -> 315 | P4: =AVERAGEIFS('Analisis semanal'!D4:D1048576,'Analisis semanal'!C4:C1048576,"reich") -> 0.5969843 | Q4: =SUMIFS(Data!J4:J1048576,Data!Q4:Q1048576,"reich") -> 3113.5 | R4: =O4/N4 -> 26.25 | T4: =COUNTIF(Data!Q5:Q1048576,"rojo") -> 11 | U4: =SUMIFS(Data!G4:G1048576,Data!Q4:Q1048576,"rojo") -> 221 | V4: =AVERAGEIFS('Analisis semanal'!D4:D1048576,'Analisis semanal'!C4:C1048576,"rojo") -> 0.65466306 | W4: =SUMIFS(Data!J4:J1048576,Data!Q4:Q1048576,"rojo") -> 2206 | X4: =U4/T4 -> 20.090909
B6: $ por tour | C6: pax x tour | D6: Bookings | E6: pronostico X | H6: $ por tour | I6: pax x tour | J6: Bookings | K6: pronostico X | N6: $ por tour | O6: tip x pax | P6: Bookings | Q6: pronostico X | T6: $ por tour | U6: tip x pax | V6: Bookings | W6: pronostico X
B7: =E4/B4 -> 248.0649 | C7: =C4/B4 -> 25.05298 | D7: =SUMIFS(Data!K4:K1048576,Data!Q4:Q1048576,"city corto") -> 5204 | E7: =B7-(C7*2.5) -> 185.43245 | H7: =K4/H4 -> 243.5 | I7: =I4/H4 -> 24.5 | J7: =SUMIFS(Data!K4:K1048576,Data!Q4:Q1048576,"city largo") -> 374 | K7: =I7*M4 -> 243.5 | N7: =Q4/N4 -> 259.45833 | O7: =Q4/O4 -> 9.884127 | P7: =SUMIFS(Data!K4:K1048576,Data!Q4:Q1048576,"reich") -> 517 | Q7: =R4*O7 -> 259.45833 | T7: =W4/T4 -> 200.54545 | U7: =W4/U4 -> 9.9819005 | V7: =SUMIFS(Data!K4:K1048576,Data!Q4:Q1048576,"rojo") -> 345 | W7: =X4*U7 -> 200.54545
B9: Tour Español | H9: Tour Ingles
B10: Qt tours | C10: QT pax | D10: Asistencia | E10: Total $ | F10: X Pax | G10: Tip x pax | H10: Qt tours | I10: QT pax | J10: Asistencia | K10: Total $ | L10: X Pax | M10: Tip x pax
B11: =COUNTIF(Data!F5:F1048576,"español") -> 83 | C11: =SUMIFS(Data!G4:G1048576,Data!F4:F1048576,"español") -> 2015 | D11: =C11/D14 -> 0.75242718 | E11: =SUMIFS(Data!J4:J1048576,Data!F4:F1048576,"español") -> 20374.4 | F11: =C11/B11 -> 24.277108 | G11: =E11/C11 -> 10.111365 | H11: =COUNTIF(Data!F5:F1048576,"ingles") -> 105 | I11: =SUMIFS(Data!G4:G1048576,Data!F4:F1048576,"ingles") -> 2874 | J11: =I11/J14 -> 0.6938677 | K11: =SUMIFS(Data!J4:J1048576,Data!F4:F1048576,"ingles") -> 28193.9 | L11: =I11/H11 -> 27.371429 | M11: =K11/I11 -> 9.8099861
B13: $ por tour | C13: pax x tour | D13: Bookings | H13: $ por tour | I13: pax x tour | J13: Bookings
B14: =E11/B11 -> 245.4747 | C14: =C11/B11 -> 24.277108 | D14: =SUMIFS(Data!K4:K1048576,Data!F4:F1048576,"español") -> 2678 | H14: =K11/H11 -> 268.51333 | I14: =I11/H11 -> 27.371429 | J14: =SUMIFS(Data!K4:K1048576,Data!F4:F1048576,"ingles") -> 4142

Sheet Analisis de dias
A3: Lunes 16/1 | B3: Dias ws | C3: Qt per | D3: Qt per X | E3: Tip Total | F3: Tip promedio | G3: Tip promedio persona | H3: X asistencia
A4: Lunes | B4: =COUNTIF('Analisis semanal'!A4:A618,"lunes") -> 22 | C4: =SUMIFS(Data!G4:G1048576,Data!C4:C1048576,"lunes") -> 595 | D4: =C4/B4 -> 27.045455 | E4: =SUMIFS(Data!J4:J1048576,Data!C4:C1048576,"lunes") -> 5986.5 | F4: =E4/B4 -> 272.11364 | G4: =F4/D4 -> 10.061345 | H4: =AVERAGEIFS('Analisis semanal'!D4:D1048576,'Analisis semanal'!A4:A1048576,"lunes") -> 0.6920253
A5: Martes | B5: =COUNTIF('Analisis semanal'!A4:A522,"martes") -> 20 | C5: =SUMIFS(Data!G4:G1048576,Data!C4:C1048576,"martes") -> 501 | D5: =C5/B5 -> 25.05 | E5: =SUMIFS(Data!J4:J1048576,Data!C4:C1048576,"martes") -> 5162 | F5: =E5/B5 -> 258.1 | G5: =F5/D5 -> 10.303393 | H5: =AVERAGEIFS('Analisis semanal'!D4:D1048576,'Analisis semanal'!A4:A1048576,"martes") -> 0.74061725
A6: Miercoles | B6: =COUNTIF('Analisis semanal'!A4:A436,"miercoles") -> 20 | C6: =SUMIFS(Data!G4:G1048576,Data!C4:C1048576,"miercoles") -> 418 | D6: =C6/B6 -> 20.9 | E6: =SUMIFS(Data!J4:J1048576,Data!C4:C1048576,"miercoles") -> 4450.4 | F6: =E6/B6 -> 222.52 | G6: =F6/D6 -> 10.64689 | H6: =AVERAGEIFS('Analisis semanal'!D4:D1048576,'Analisis semanal'!A4:A1048576,"miercoles") -> 0.76358254
A7: Jueves | B7: =COUNTIF('Analisis semanal'!A4:A436,"jueves") -> 23 | C7: =SUMIFS(Data!G4:G1048576,Data!C4:C1048576,"jueves") -> 641 | D7: =C7/B7 -> 27.869565 | E7: =SUMIFS(Data!J4:J1048576,Data!C4:C1048576,"jueves") -> 5883.5 | F7: =E7/B7 -> 255.80435 | G7: =F7/D7 -> 9.1786271 | H7: =AVERAGEIFS('Analisis semanal'!D4:D1048576,'Analisis semanal'!A4:A1048576,"jueves") -> 0.78350913
A8: viernes | B8: =COUNTIF('Analisis semanal'!A4:A436,"viernes") -> 25 | C8: =SUMIFS(Data!G4:G1048576,Data!C4:C1048576,"viernes") -> 709 | D8: =C8/B8 -> 28.36 | E8: =SUMIFS(Data!J4:J1048576,Data!C4:C1048576,"viernes") -> 6808 | F8: =E8/B8 -> 272.32 | G8: =F8/D8 -> 9.6022567 | H8: =AVERAGEIFS('Analisis semanal'!D4:D1048576,'Analisis semanal'!A4:A1048576,"viernes") -> 0.77812581
A9: Sabado | B9: =COUNTIF('Analisis semanal'!A4:A436,"sabado") -> 43 | C9: =SUMIFS(Data!G4:G1048576,Data!C4:C1048576,"sabado") -> 1211 | D9: =C9/B9 -> 28.162791 | E9: =SUMIFS(Data!J4:J1048576,Data!C4:C1048576,"sabado") -> 11943.5 | F9: =E9/B9 -> 277.75581 | G9: =F9/D9 -> 9.8625103 | H9: =AVERAGEIFS('Analisis semanal'!D4:D1048576,'Analisis semanal'!A4:A1048576,"sabado") -> 0.71831834
A10: Domingo | B10: =COUNTIF('Analisis semanal'!A4:A436,"domingo") -> 35 | C10: =SUMIFS(Data!G4:G1048576,Data!C4:C1048576,"domingo") -> 814 | D10: =C10/B10 -> 23.257143 | E10: =SUMIFS(Data!J4:J1048576,Data!C4:C1048576,"domingo") -> 8334.4 | F10: =E10/B10 -> 238.12571 | G10: =F10/D10 -> 10.238821 | H10: =AVERAGEIFS('Analisis semanal'!D4:D1048576,'Analisis semanal'!A4:A1048576,"domingo") -> 0.70296773
B11: =SUM(B4:B10) -> 188 | C11: =SUM(C4:C10) -> 4889 | D11: =AVERAGE(D4:D10) -> 25.806422 | E11: =SUM(E4:E10) -> 48568.3 | F11: =AVERAGE(F4:F10) -> 256.67707 | G11: =AVERAGE(G4:G10) -> 9.9848346 | H11: =AVERAGE(H4:H10) -> 0.73987801
